<mujoco model="xarm7">
    <compiler angle="radian" />
    <size njmax="500" nconmax="100" />

    <!-- These are copied from panda -->
    <actuator>
        <!-- Physical limits of the actuator. -->
        <motor ctrllimited="true" ctrlrange="-80.0 80.0" joint="joint1" name="torq_j1"/>
        <motor ctrllimited="true" ctrlrange="-80.0 80.0" joint="joint2" name="torq_j2"/>
        <motor ctrllimited="true" ctrlrange="-80.0 80.0" joint="joint3" name="torq_j3"/>
        <motor ctrllimited="true" ctrlrange="-80.0 80.0" joint="joint4" name="torq_j4"/>
        <motor ctrllimited="true" ctrlrange="-80.0 80.0" joint="joint5" name="torq_j5"/>
        <motor ctrllimited="true" ctrlrange="-80.0 80.0" joint="joint6" name="torq_j6"/>
        <motor ctrllimited="true" ctrlrange="-12.0 12.0" joint="joint7" name="torq_j7"/>
    </actuator>

    <asset>
        <mesh name="link_base" file="meshes/link_base.stl" />
        <mesh name="link1" file="meshes/link1.stl" />
        <mesh name="link2" file="meshes/link2.stl" />
        <mesh name="link3" file="meshes/link3.stl" />
        <mesh name="link4" file="meshes/link4.stl" />
        <mesh name="link5" file="meshes/link5.stl" />
        <mesh name="link6" file="meshes/link6.stl" />
        <mesh name="link7" file="meshes/link7.stl" />

        <!-- Custom textures based on body names for domain randomization -->
        <texture type="cube" name="pedestal_tex" builtin="flat" width="100" height="100" rgb1="0.2 0.2 0.2" rgb2="0.2 0.2 0.2"/>
        <texture type="cube" name="torso_tex" builtin="flat" width="100" height="100" rgb1="0.2 0.2 0.2" rgb2="0.2 0.2 0.2"/>
        <texture type="cube" name="arm_tex" builtin="flat" width="100" height="100" rgb1="1 1 1" rgb2="1 1 1"/>

        <!-- Custom mats based on body names for domain randomization -->
        <material name="pedestal_mat" texture="pedestal_tex"/>
        <material name="torso_mat" texture="torso_tex"/>
        <material name="arm_mat" texture="arm_tex"/>
    </asset>
    <worldbody>

        <!-- This part copied from xarm6 to add pedestal -->
        <body name="link0" pos="0 0 0">
            <body name="base" pos="0 0 0">

                <!-- robot view -->
                <camera mode="fixed" name="robotview" pos="1.0 0 0.4" quat="0.653 0.271 0.271 0.653"/>
                <inertial diaginertia="0 0 0" mass="0" pos="0 0 0"/>
                <body name="controller_box" pos="0 0 0">
                    <inertial diaginertia="1.71363 1.27988 0.809981" mass="46.64" pos="-0.325 0 -0.38"/>
                    <geom pos="-0.325 0 -0.38" size="0.11 0.2 0.265" type="box" name="controller_box_col"/>
                </body>
            </body>

            <geom type="mesh" contype="0" conaffinity="0" group="1" rgba="1 1 1 1" mesh="link_base" />
            <geom type="mesh" contype="0" conaffinity="0" group="1" rgba="1 1 1 1" mesh="link_base" name="link_base_collision"/>

            <body name="link1" pos="0 0 0.267">
                <inertial pos="-0.0042142 0.02821 -0.0087788" quat="0.917781 -0.277115 0.0606681 0.277858" mass="0.42603" diaginertia="0.00144551 0.00137757 0.000823511" />
                <joint name="joint1" pos="0 0 0" axis="0 0 1" limited="true" range="-6.28319 6.28319" damping="10" frictionloss="1" />
                <geom type="mesh" contype="0" conaffinity="0" group="1" rgba="1 1 1 1" mesh="link1" />
                <geom type="mesh" contype="0" conaffinity="0" group="1" rgba="1 1 1 1" mesh="link1" name="link1_collision"/>
                <body name="link2" pos="0 0 0" quat="0.707105 -0.707108 0 0">
                    <inertial pos="-3.3178e-05 -0.12849 0.026337" quat="0.447793 0.894132 -0.00224061 0.00218314" mass="0.56095" diaginertia="0.00319151 0.00311598 0.000980804" />
                    <joint name="joint2" pos="0 0 0" axis="0 0 1" limited="true" range="-2.059 2.0944" damping="10" frictionloss="1" />
                    <geom type="mesh" contype="0" conaffinity="0" group="1"  rgba="1 1 1 1" mesh="link2" />
                    <body name="link3" pos="0 -0.293 0" quat="0.707105 0.707108 0 0">
                        <inertial pos="0.04223 -0.023258 -0.0096674" quat="0.883205 0.339803 0.323238 0.000542237" mass="0.44463" diaginertia="0.00133227 0.00119126 0.000780475" />
                        <joint name="joint3" pos="0 0 0" axis="0 0 1" limited="true" range="-6.28319 6.28319" damping="5" frictionloss="1" />
                        <geom type="mesh"  contype="0" conaffinity="0" group="1"  rgba="1 1 1 1" mesh="link3" />
                        <body name="link4" pos="0.0525 0 0" quat="0.707105 0.707108 0 0">
                            <inertial pos="0.067148 -0.10732 0.024479" quat="0.0654142 0.483317 -0.738663 0.465298" mass="0.52387" diaginertia="0.00288984 0.00282705 0.000894409" />
                            <joint name="joint4" pos="0 0 0" axis="0 0 1" limited="true" range="-0.19198 3.927" damping="5" frictionloss="1" />
                            <geom type="mesh" contype="0" conaffinity="0" group="1"  rgba="1 1 1 1" mesh="link4" />
                            <body name="link5" pos="0.0775 -0.3425 0" quat="0.707105 0.707108 0 0">
                                <inertial pos="-0.00023397 0.036705 -0.080064" quat="0.981064 -0.19003 0.00637998 0.0369004" mass="0.18554" diaginertia="0.00099553 0.000988613 0.000247126" />
                                <joint name="joint5" pos="0 0 0" axis="0 0 1" limited="true" range="-6.28319 6.28319" damping="5" frictionloss="1" />
                                <geom type="mesh" contype="0" conaffinity="0" group="1"  rgba="1 1 1 1" mesh="link5" />
                                <body name="link6" pos="0 0 0" quat="0.707105 0.707108 0 0">
                                    <inertial pos="0.058911 0.028469 0.0068428" quat="-0.188705 0.793535 0.166088 0.554173" mass="0.31344" diaginertia="0.000827892 0.000768871 0.000386708" />
                                    <joint name="joint6" pos="0 0 0" axis="0 0 1" limited="true" range="-1.69297 3.14159" damping="2" frictionloss="1" />
                                    <geom type="mesh"  contype="0" conaffinity="0" group="1" rgba="1 1 1 1" mesh="link6" />
                                    <body name="link7" pos="0.076 0.097 0" quat="0.707105 -0.707108 0 0">
                                        <inertial pos="-1.5846e-05 -0.0046377 -0.012705" quat="0.495801 0.504435 -0.503065 0.496642" mass="0.31468" diaginertia="0.000260352 0.00016985 0.000119208" />
                                        <joint name="joint7" pos="0 0 0" axis="0 0 1" limited="true" range="-6.28319 6.28319" damping="2" frictionloss="1" />
                                        <geom type="mesh"  contype="0" conaffinity="0" group="1" rgba="0.753 0.753 0.753 1" mesh="link7" />

                                        <!-- end effector stuff -->
                                        <body name="right_hand" pos="0 0 -0.01" euler="0 0 0">
                                            <inertial pos="0 0 0" mass="0.5" diaginertia="0.05 0.05 0.05" />
                                            <!-- This sites were added for visualization. They are all standardized between models-->
                                            <!-- Position mimics the gripper attachment point (right_hand) -->
                                            <!--  Y-axis should be perpendicular to grasping motion, and Z-axis should point out of the robot eef -->
                                            <site name="ee" pos="0 0 0" size="0.01 0.01 0.01" rgba="0 0 1 1" type="sphere" group="1"/>
                                            <site name="ee_x" pos="0 0 0" size="0.005 .1"  quat="0.707105 0.707108 0 0 " rgba="1 0 0 0" type="cylinder" group="1"/>
                                            <site name="ee_z" pos="0 0 0" size="0.005 .1" quat="0.707105 0 0 0.707108" rgba="0 0 1 0" type="cylinder" group="1"/>
                                            <site name="ee_y" pos="0 0 0" size="0.005 .1" quat="0.707105 0 0.707108 0 " rgba="0 1 0 0" type="cylinder" group="1"/>
                                            <!-- This camera points out from the eef. -->
                                            <camera mode="fixed" name="eye_in_hand" pos="0.05 0 0" quat="0 0.707108 0.707108 0" fovy="75"/>
                                            <!-- to add gripper -->
                                        </body>

                                    </body>
                                </body>
                            </body>
                        </body>
                    </body>
                </body>
            </body>
        </body>
    </worldbody>
</mujoco>
